<robot xmlns:xacro="http://ros.org/wiki/xacro" name="robot_essentials" >


<!--ROBOT WHEEL-->
<xacro:macro name="robot_wheel" params="prefix">

<link name="${prefix}_wheel">
    <visual>
        <geometry>
            <mesh filename="package://mobile_manipulator/meshes/left_wheel.stl" scale="0.15 0.15 0.15"/>
        </geometry>
        <origin xyz="0 0 0" rpy="1.57 0 -1.57"/>
    </visual>
    <collision>
        <origin xyz="0 0 0" rpy="1.57 0 -1.57"/>
        <geometry>
            <mesh filename="package://mobile_manipulator/meshes/left_wheel.stl" scale="0.15 0.15 0.15"/>
        </geometry>
    </collision>
    <inertial>
        <origin xyz="0 0 0" rpy="0 0 0"/>
        <mass value="2.5"/>
        <inertia ixx="0.00856502765719703"
        ixy="1.5074118157338E-19"
        ixz="-4.78150098725052E-19"
        iyy="0.013670640432096"
        iyz="-2.68136447099727E-19"
        izz="0.00856502765719703" />
    </inertial>
    
    
</link>

</xacro:macro>

<!--WHEEL JOINT-->
<xacro:macro name="wheel_joint" params="prefix origin">

<joint name="${prefix}_wheel_joint" type="continuous">
    <axis xyz="0 1 0"/>
    <parent link ="base_link"/>
    <child link ="${prefix}_wheel"/>
    <origin rpy ="0 0 0" xyz= "${origin}"/>
  </joint>

</xacro:macro>

<!--TRANSMISSION-->
<xacro:macro name="base_transmission" params="prefix ">

<transmission name="${prefix}_wheel_trans" type="SimpleTransmission">
  <type>transmission_interface/SimpleTransmission</type>
  <actuator name="${prefix}_wheel_motor">
   <hardwareInterface>hardware_interface/VelocityJointInterface</hardwareInterface>
   <mechanicalReduction>1</mechanicalReduction>
  </actuator>
  <joint name="${prefix}_wheel_joint">
   <hardwareInterface>hardware_interface/VelocityJointInterface</hardwareInterface>
  </joint>
</transmission>

</xacro:macro>


</robot>
